[2018-09-12 20:24:57,048][Thread-1:17064][task_id:django.request][log.py:228][ERROR][Internal Server Error: /]
Traceback (most recent call last):
  File "d:\software\python35\lib\site-packages\django\core\handlers\exception.py", line 34, in inner
    response = get_response(request)
  File "d:\software\python35\lib\site-packages\django\core\handlers\base.py", line 126, in _get_response
    response = self.process_exception_by_middleware(e, request)
  File "d:\software\python35\lib\site-packages\django\core\handlers\base.py", line 124, in _get_response
    response = wrapped_callback(request, *callback_args, **callback_kwargs)
TypeError: showMainPage() missing 1 required positional argument: 'path'
[2018-09-12 20:25:21,707][Thread-4:8316][task_id:django.request][log.py:228][ERROR][Internal Server Error: /]
Traceback (most recent call last):
  File "d:\software\python35\lib\site-packages\django\core\handlers\exception.py", line 34, in inner
    response = get_response(request)
  File "d:\software\python35\lib\site-packages\django\core\handlers\base.py", line 126, in _get_response
    response = self.process_exception_by_middleware(e, request)
  File "d:\software\python35\lib\site-packages\django\core\handlers\base.py", line 124, in _get_response
    response = wrapped_callback(request, *callback_args, **callback_kwargs)
TypeError: showMainPage() missing 1 required positional argument: 'path'
[2018-09-12 20:26:01,731][Thread-9:15532][task_id:django.request][log.py:228][ERROR][Internal Server Error: /icon.png]
Traceback (most recent call last):
  File "d:\software\python35\lib\site-packages\django\core\handlers\exception.py", line 34, in inner
    response = get_response(request)
  File "d:\software\python35\lib\site-packages\django\core\handlers\base.py", line 126, in _get_response
    response = self.process_exception_by_middleware(e, request)
  File "d:\software\python35\lib\site-packages\django\core\handlers\base.py", line 124, in _get_response
    response = wrapped_callback(request, *callback_args, **callback_kwargs)
  File "D:\Project\ShadowInk\my\views.py", line 45, in showPath
    html = f.read()
  File "d:\software\python35\lib\codecs.py", line 321, in decode
    (result, consumed) = self._buffer_decode(data, self.errors, final)
UnicodeDecodeError: 'utf-8' codec can't decode byte 0x89 in position 0: invalid start byte
[2018-09-12 20:26:01,834][Thread-11:15604][task_id:django.request][log.py:228][ERROR][Internal Server Error: /login_files/icon_2x.png]
Traceback (most recent call last):
  File "d:\software\python35\lib\site-packages\django\core\handlers\exception.py", line 34, in inner
    response = get_response(request)
  File "d:\software\python35\lib\site-packages\django\core\handlers\base.py", line 126, in _get_response
    response = self.process_exception_by_middleware(e, request)
  File "d:\software\python35\lib\site-packages\django\core\handlers\base.py", line 124, in _get_response
    response = wrapped_callback(request, *callback_args, **callback_kwargs)
  File "D:\Project\ShadowInk\my\views.py", line 45, in showPath
    html = f.read()
  File "d:\software\python35\lib\codecs.py", line 321, in decode
    (result, consumed) = self._buffer_decode(data, self.errors, final)
UnicodeDecodeError: 'utf-8' codec can't decode byte 0x89 in position 0: invalid start byte
[2018-09-12 20:29:54,554][Thread-9:8172][task_id:django.request][log.py:228][ERROR][Internal Server Error: /]
Traceback (most recent call last):
  File "d:\software\python35\lib\site-packages\django\core\handlers\exception.py", line 34, in inner
    response = get_response(request)
  File "d:\software\python35\lib\site-packages\django\core\handlers\base.py", line 126, in _get_response
    response = self.process_exception_by_middleware(e, request)
  File "d:\software\python35\lib\site-packages\django\core\handlers\base.py", line 124, in _get_response
    response = wrapped_callback(request, *callback_args, **callback_kwargs)
TypeError: showMainPage() missing 1 required positional argument: 'path'
[2018-09-12 20:32:04,399][Thread-1:10792][task_id:django.request][log.py:228][ERROR][Internal Server Error: /]
Traceback (most recent call last):
  File "d:\software\python35\lib\site-packages\django\core\handlers\exception.py", line 34, in inner
    response = get_response(request)
  File "d:\software\python35\lib\site-packages\django\core\handlers\base.py", line 126, in _get_response
    response = self.process_exception_by_middleware(e, request)
  File "d:\software\python35\lib\site-packages\django\core\handlers\base.py", line 124, in _get_response
    response = wrapped_callback(request, *callback_args, **callback_kwargs)
TypeError: showMainPage() missing 1 required positional argument: 'path'
